Workbook

Sheet Core
A1: Personal Info | E1: Combat Info | L1: Clim Total Available
A2: Name | C2: Race | E2: HP | F2: =20+(10*B12)+H7 -> 70 | G2: Evasion | H2: =7+B11+E33+SUMIF($L$37:$L$42,TRUE,$H$37:$H$42) -> 11 | I2: Dodge | K2: =20+B11+H33+SUMIF($L$37:$L$42,TRUE,$I$37:$I$42) -> 24 | L2: ='EXP & Transactions'!G2 -> 4000
A3: Gender | C3: Sub-Race | House | E3: Mana | F3: =ROUNDDOWN(6+(B10)+(K34),0) -> 10 | G3: Guard | H3: =ROUNDDOWN(B12+K4,0) -> 5 | I3: Block | K3: =(B12*2)+SUMIF($L$37:$L$42,TRUE,$J$37:$J$42) -> 10
A4: Age | C4: Exp | D4: ='EXP & Transactions'!D2 - SUM(D7,D15:D35) -> 1000 | E4: Initiative | F4: =B11+H35-SUMIF($L$37:$L$42,TRUE,$K$37:$K$42) -> 4 | G4: Save Bonus | H4: =B12+G34 -> 5 | I4: Equipment Guard Value | K4: =SUMIF($L$37:$L$42,TRUE,$G$37:$G$42) -> 0
A5: Height | C5: Spirit Core | D5: =D4 + D7 + SUM(D15:D35) -> 1000 | E5: Light Damage | F5: =D37 | G5: Potency | H5: =11+B9 -> 14 | I5: Equipment Block Value | K5: =SUMIF($L$37:$L$42,TRUE,$J$37:$J$42) -> 0
A6: Weight | C6: 6/14/2026 | D6: 6/14/2026 | E6: Heavy Damage | F6: =E37 | G6: Speed | H6: 20 | I6: Equipment Penalty | K6: =SUMIF($L$37:$L$42,TRUE,$H$37:$H$42) -> 0
A7: Worships | B7: RNGesus | C7: Breakthrough | D7: =SUM(Breakthrough!B2:B58) -> 0 | E7: RP | F7: =IF(K30, 2 + (B11 - K6), 2 + B11)-E35 -> 6 | G7: HP Bonus | H7: 0 | I7: Combat Burden | K7: =Inventory!H32 -> 0
A8: Main Stats | C8: Sub-Stats | E8: Skill | F8: Stat | G8: Bonus | H8: Skill Points | I8: Expertise | K8: Proficiencies | M8: Crafting Skill | N8: Total Bonus | O8: Skill Points | P8: Equipment Bonus
A9: Focus | B9: =IFS(B45 = A9, A45, B46 = A9, A46, B47 = A9, A47, B48 = A9, A48)+F45 -> 3 | C9: Fitness | D9: =IFS(D45 = C9, C45, D46 = C9, C46, D47 = C9, C47, D48 = C9, C48, D49 = C9, C49)+H45 -> 5 | E9: Athletics | F9: Fitness | G9: =D9+H9 -> 5 | H9: 0 | K9: Armor | N9: =O9+P9 -> 0 | O9: 0
A10: Power | B10: =IFS(B45 = A10, A45, B46 = A10, A46, B47 = A10, A47, B48 = A10, A48)+F46 -> 4 | C10: Cunning | D10: =IFS(D45 = C10, C45, D46 = C10, C46, D47 = C10, C47, D48 = C10, C48, D49 = C10, C49)+H46 -> 4 | E10: Riding | F10: Fitness | G10: =D9+H10 -> 5 | H10: 0 | K10: Language | N10: =O10+P10 -> 0 | O10: 0
A11: Agility | B11: =IFS(B45 = A11, A45, B46 = A11, A46, B47 = A11, A47, B48 = A11, A48)+F47-P34+O34 -> 4 | C11: Reason | D11: =IFS(D45 = C11, C45, D46 = C11, C46, D47 = C11, C47, D48 = C11, C48, D49 = C11, C49)+H47 -> 3 | E11: Stealth | F11: Cunning | G11: =D10+H11 -> 4 | H11: 0 | K11: Weapons | N11: =O11+P11 -> 0 | O11: 0
A12: Toughness | B12: =IFS(B45 = A12, A45, B46 = A12, A46, B47 = A12, A47, B48 = A12, A48)+F48-N34+M34 -> 5 | C12: Awareness | D12: =IFS(D45 = C12, C45, D46 = C12, C46, D47 = C12, C47, D48 = C12, C48,D49 = C12, C49)+H48 -> 2 | E12: Deception | F12: Cunning | G12: =D10+H12 -> 4 | H12: 0 | K12: Elemental Mastery | N12: =O12+P12 -> 0 | O12: 0
C13: Presence | D13: =IFS(D45 = C13, C45, D46 = C13, C46, D47 = C13, C47, D48 = C13, C48,D49 = C13, C49)+H49 -> 1 | E13: Roguecraft | F13: Cunning | G13: =D10+H13 -> 4 | H13: 0 | N13: =O13+P13 -> 0 | O13: 0
A14: Class | B14: Class Tier | C14: Class Level | D14: Cost (EXP) | E14: Medicine | F14: Reason | G14: =D11+H14 -> 3 | H14: 0 | N14: =O14+P14 -> 0 | O14: 0
B15: =IFERROR(__xludf.DUMMYFUNCTION("IFERROR(INDEX(IMPORTRANGE(""https://docs.google.com/spreadsheets/d/1xgDM68xiM34Lb7pPa9X0VaOqdhswjHKkl6KIk-vu_2Q/edit?gid=0#gid=0"",""Classes!C2:C""),MATCH(A15,IMPORTRANGE(""https://docs.google.com/spreadsheets/d/1xgDM68xiM34Lb7pPa9X0VaOqdhswjHKkl6KIk-vu_2"&"Q/edit?gid=0#gid=0"",""Classes!B2:B""),0)),"""")"),"") | D15: 0 | E15: Common Knowledge | F15: Reason | G15: =D11+H15 -> 3 | H15: 0 | N15: =O15+P15 -> 0 | O15: 0
B16: =IFERROR(__xludf.DUMMYFUNCTION("IFERROR(INDEX(IMPORTRANGE(""https://docs.google.com/spreadsheets/d/1xgDM68xiM34Lb7pPa9X0VaOqdhswjHKkl6KIk-vu_2Q/edit?gid=0#gid=0"",""Classes!C2:C""),MATCH(A16,IMPORTRANGE(""https://docs.google.com/spreadsheets/d/1xgDM68xiM34Lb7pPa9X0VaOqdhswjHKkl6KIk-vu_2"&"Q/edit?gid=0#gid=0"",""Classes!B2:B""),0)),"""")"),"") | D16: 0 | E16: Linguistics | F16: Reason | G16: =D11+H16 -> 3 | H16: 0 | N16: =O16+P16 -> 0 | O16: 0
B17: =IFERROR(__xludf.DUMMYFUNCTION("IFERROR(INDEX(IMPORTRANGE(""https://docs.google.com/spreadsheets/d/1xgDM68xiM34Lb7pPa9X0VaOqdhswjHKkl6KIk-vu_2Q/edit?gid=0#gid=0"",""Classes!C2:C""),MATCH(A17,IMPORTRANGE(""https://docs.google.com/spreadsheets/d/1xgDM68xiM34Lb7pPa9X0VaOqdhswjHKkl6KIk-vu_2"&"Q/edit?gid=0#gid=0"",""Classes!B2:B""),0)),"""")"),"") | D17: 0 | E17: Magic | F17: Reason | G17: =D11+H17 -> 3 | H17: 0 | N17: =O17+P17 -> 0 | O17: 0
B18: =IFERROR(__xludf.DUMMYFUNCTION("IFERROR(INDEX(IMPORTRANGE(""https://docs.google.com/spreadsheets/d/1xgDM68xiM34Lb7pPa9X0VaOqdhswjHKkl6KIk-vu_2Q/edit?gid=0#gid=0"",""Classes!C2:C""),MATCH(A18,IMPORTRANGE(""https://docs.google.com/spreadsheets/d/1xgDM68xiM34Lb7pPa9X0VaOqdhswjHKkl6KIk-vu_2"&"Q/edit?gid=0#gid=0"",""Classes!B2:B""),0)),"""")"),"") | D18: 0 | E18: Religion | F18: Reason | G18: =D11+H18 -> 3 | H18: 0 | N18: =O18+P18 -> 0 | O18: 0
B19: =IFERROR(__xludf.DUMMYFUNCTION("IFERROR(INDEX(IMPORTRANGE(""https://docs.google.com/spreadsheets/d/1xgDM68xiM34Lb7pPa9X0VaOqdhswjHKkl6KIk-vu_2Q/edit?gid=0#gid=0"",""Classes!C2:C""),MATCH(A19,IMPORTRANGE(""https://docs.google.com/spreadsheets/d/1xgDM68xiM34Lb7pPa9X0VaOqdhswjHKkl6KIk-vu_2"&"Q/edit?gid=0#gid=0"",""Classes!B2:B""),0)),"""")"),"") | D19: 0 | E19: Appraise | F19: Reason | G19: =D11+H19 -> 3 | H19: 0 | N19: =O19+P19 -> 0 | O19: 0
B20: =IFERROR(__xludf.DUMMYFUNCTION("IFERROR(INDEX(IMPORTRANGE(""https://docs.google.com/spreadsheets/d/1xgDM68xiM34Lb7pPa9X0VaOqdhswjHKkl6KIk-vu_2Q/edit?gid=0#gid=0"",""Classes!C2:C""),MATCH(A20,IMPORTRANGE(""https://docs.google.com/spreadsheets/d/1xgDM68xiM34Lb7pPa9X0VaOqdhswjHKkl6KIk-vu_2"&"Q/edit?gid=0#gid=0"",""Classes!B2:B""),0)),"""")"),"") | D20: 0 | E20: History | F20: Reason | G20: =D11+H20 -> 3 | H20: 0 | N20: =O20+P20 -> 0 | O20: 0
B21: =IFERROR(__xludf.DUMMYFUNCTION("IFERROR(INDEX(IMPORTRANGE(""https://docs.google.com/spreadsheets/d/1xgDM68xiM34Lb7pPa9X0VaOqdhswjHKkl6KIk-vu_2Q/edit?gid=0#gid=0"",""Classes!C2:C""),MATCH(A21,IMPORTRANGE(""https://docs.google.com/spreadsheets/d/1xgDM68xiM34Lb7pPa9X0VaOqdhswjHKkl6KIk-vu_2"&"Q/edit?gid=0#gid=0"",""Classes!B2:B""),0)),"""")"),"") | D21: 0 | E21: Flight | F21: Reason | G21: =D11+H21 -> 3 | H21: 0 | N21: =O21+P21 -> 0 | O21: 0
B22: =IFERROR(__xludf.DUMMYFUNCTION("IFERROR(INDEX(IMPORTRANGE(""https://docs.google.com/spreadsheets/d/1xgDM68xiM34Lb7pPa9X0VaOqdhswjHKkl6KIk-vu_2Q/edit?gid=0#gid=0"",""Classes!C2:C""),MATCH(A22,IMPORTRANGE(""https://docs.google.com/spreadsheets/d/1xgDM68xiM34Lb7pPa9X0VaOqdhswjHKkl6KIk-vu_2"&"Q/edit?gid=0#gid=0"",""Classes!B2:B""),0)),"""")"),"") | D22: 0 | E22: Artifice | F22: Reason | G22: =D11+H22 -> 3 | H22: 0 | N22: =O22+P22 -> 0 | O22: 0
B23: =IFERROR(__xludf.DUMMYFUNCTION("IFERROR(INDEX(IMPORTRANGE(""https://docs.google.com/spreadsheets/d/1xgDM68xiM34Lb7pPa9X0VaOqdhswjHKkl6KIk-vu_2Q/edit?gid=0#gid=0"",""Classes!C2:C""),MATCH(A23,IMPORTRANGE(""https://docs.google.com/spreadsheets/d/1xgDM68xiM34Lb7pPa9X0VaOqdhswjHKkl6KIk-vu_2"&"Q/edit?gid=0#gid=0"",""Classes!B2:B""),0)),"""")"),"") | D23: 0 | E23: Perception | F23: Awareness | G23: =D12+H23 -> 2 | H23: 0 | N23: =O23+P23 -> 0 | O23: 0
B24: =IFERROR(__xludf.DUMMYFUNCTION("IFERROR(INDEX(IMPORTRANGE(""https://docs.google.com/spreadsheets/d/1xgDM68xiM34Lb7pPa9X0VaOqdhswjHKkl6KIk-vu_2Q/edit?gid=0#gid=0"",""Classes!C2:C""),MATCH(A24,IMPORTRANGE(""https://docs.google.com/spreadsheets/d/1xgDM68xiM34Lb7pPa9X0VaOqdhswjHKkl6KIk-vu_2"&"Q/edit?gid=0#gid=0"",""Classes!B2:B""),0)),"""")"),"") | D24: 0 | E24: Insight | F24: Awareness | G24: =D12+H24 -> 2 | H24: 0 | N24: =O24+P24 -> 0 | O24: 0
B25: =IFERROR(__xludf.DUMMYFUNCTION("IFERROR(INDEX(IMPORTRANGE(""https://docs.google.com/spreadsheets/d/1xgDM68xiM34Lb7pPa9X0VaOqdhswjHKkl6KIk-vu_2Q/edit?gid=0#gid=0"",""Classes!C2:C""),MATCH(A25,IMPORTRANGE(""https://docs.google.com/spreadsheets/d/1xgDM68xiM34Lb7pPa9X0VaOqdhswjHKkl6KIk-vu_2"&"Q/edit?gid=0#gid=0"",""Classes!B2:B""),0)),"""")"),"") | D25: 0 | E25: Survival | F25: Awareness | G25: =D12+H25 -> 2 | H25: 0 | N25: =O25+P25 -> 0 | O25: 0
B26: =IFERROR(__xludf.DUMMYFUNCTION("IFERROR(INDEX(IMPORTRANGE(""https://docs.google.com/spreadsheets/d/1xgDM68xiM34Lb7pPa9X0VaOqdhswjHKkl6KIk-vu_2Q/edit?gid=0#gid=0"",""Classes!C2:C""),MATCH(A26,IMPORTRANGE(""https://docs.google.com/spreadsheets/d/1xgDM68xiM34Lb7pPa9X0VaOqdhswjHKkl6KIk-vu_2"&"Q/edit?gid=0#gid=0"",""Classes!B2:B""),0)),"""")"),"") | D26: 0 | E26: Animal Husbandry | F26: Awareness | G26: =D12+H26 -> 2 | H26: 0 | N26: =O26+P26 -> 0 | O26: 0
B27: =IFERROR(__xludf.DUMMYFUNCTION("IFERROR(INDEX(IMPORTRANGE(""https://docs.google.com/spreadsheets/d/1xgDM68xiM34Lb7pPa9X0VaOqdhswjHKkl6KIk-vu_2Q/edit?gid=0#gid=0"",""Classes!C2:C""),MATCH(A27,IMPORTRANGE(""https://docs.google.com/spreadsheets/d/1xgDM68xiM34Lb7pPa9X0VaOqdhswjHKkl6KIk-vu_2"&"Q/edit?gid=0#gid=0"",""Classes!B2:B""),0)),"""")"),"") | D27: 0 | E27: Art | F27: Presence | G27: =D13+H27 -> 1 | H27: 0 | N27: =O27+P27 -> 0 | O27: 0
B28: =IFERROR(__xludf.DUMMYFUNCTION("IFERROR(INDEX(IMPORTRANGE(""https://docs.google.com/spreadsheets/d/1xgDM68xiM34Lb7pPa9X0VaOqdhswjHKkl6KIk-vu_2Q/edit?gid=0#gid=0"",""Classes!C2:C""),MATCH(A28,IMPORTRANGE(""https://docs.google.com/spreadsheets/d/1xgDM68xiM34Lb7pPa9X0VaOqdhswjHKkl6KIk-vu_2"&"Q/edit?gid=0#gid=0"",""Classes!B2:B""),0)),"""")"),"") | D28: 0 | E28: Negotiation | F28: Presence | G28: =D13+H28 -> 1 | H28: 0 | N28: =O28+P28 -> 0 | O28: 0
B29: =IFERROR(__xludf.DUMMYFUNCTION("IFERROR(INDEX(IMPORTRANGE(""https://docs.google.com/spreadsheets/d/1xgDM68xiM34Lb7pPa9X0VaOqdhswjHKkl6KIk-vu_2Q/edit?gid=0#gid=0"",""Classes!C2:C""),MATCH(A29,IMPORTRANGE(""https://docs.google.com/spreadsheets/d/1xgDM68xiM34Lb7pPa9X0VaOqdhswjHKkl6KIk-vu_2"&"Q/edit?gid=0#gid=0"",""Classes!B2:B""),0)),"""")"),"") | D29: 0 | E29: Intimidation | F29: Presence | G29: =D13+H29 -> 1 | H29: 0 | K29: Check Box if Old Armor Calc | N29: =O29+P29 -> 0 | O29: 0
B30: =IFERROR(__xludf.DUMMYFUNCTION("IFERROR(INDEX(IMPORTRANGE(""https://docs.google.com/spreadsheets/d/1xgDM68xiM34Lb7pPa9X0VaOqdhswjHKkl6KIk-vu_2Q/edit?gid=0#gid=0"",""Classes!C2:C""),MATCH(A30,IMPORTRANGE(""https://docs.google.com/spreadsheets/d/1xgDM68xiM34Lb7pPa9X0VaOqdhswjHKkl6KIk-vu_2"&"Q/edit?gid=0#gid=0"",""Classes!B2:B""),0)),"""")"),"") | D30: 0 | K30: FALSE | N30: =O30+P30 -> 0 | O30: 0
B31: =IFERROR(__xludf.DUMMYFUNCTION("IFERROR(INDEX(IMPORTRANGE(""https://docs.google.com/spreadsheets/d/1xgDM68xiM34Lb7pPa9X0VaOqdhswjHKkl6KIk-vu_2Q/edit?gid=0#gid=0"",""Classes!C2:C""),MATCH(A31,IMPORTRANGE(""https://docs.google.com/spreadsheets/d/1xgDM68xiM34Lb7pPa9X0VaOqdhswjHKkl6KIk-vu_2"&"Q/edit?gid=0#gid=0"",""Classes!B2:B""),0)),"""")"),"") | D31: 0
B32: =IFERROR(__xludf.DUMMYFUNCTION("IFERROR(INDEX(IMPORTRANGE(""https://docs.google.com/spreadsheets/d/1xgDM68xiM34Lb7pPa9X0VaOqdhswjHKkl6KIk-vu_2Q/edit?gid=0#gid=0"",""Classes!C2:C""),MATCH(A32,IMPORTRANGE(""https://docs.google.com/spreadsheets/d/1xgDM68xiM34Lb7pPa9X0VaOqdhswjHKkl6KIk-vu_2"&"Q/edit?gid=0#gid=0"",""Classes!B2:B""),0)),"""")"),"") | D32: 0 | E32: Evasion Bonus | G32: Bonus Save Value | H32: Dodge Bonus | K32: Mana Adjustments | M32: Toughness Adjustments | O32: Agility Adjustments (Racial Ability)
B33: =IFERROR(__xludf.DUMMYFUNCTION("IFERROR(INDEX(IMPORTRANGE(""https://docs.google.com/spreadsheets/d/1xgDM68xiM34Lb7pPa9X0VaOqdhswjHKkl6KIk-vu_2Q/edit?gid=0#gid=0"",""Classes!C2:C""),MATCH(A33,IMPORTRANGE(""https://docs.google.com/spreadsheets/d/1xgDM68xiM34Lb7pPa9X0VaOqdhswjHKkl6KIk-vu_2"&"Q/edit?gid=0#gid=0"",""Classes!B2:B""),0)),"""")"),"") | D33: 0 | E33: 0 | H33: 0 | K33: Add - for Negative | M33: Positive | N33: Negative | O33: Positive | P33: Negative
B34: =IFERROR(__xludf.DUMMYFUNCTION("IFERROR(INDEX(IMPORTRANGE(""https://docs.google.com/spreadsheets/d/1xgDM68xiM34Lb7pPa9X0VaOqdhswjHKkl6KIk-vu_2Q/edit?gid=0#gid=0"",""Classes!C2:C""),MATCH(A34,IMPORTRANGE(""https://docs.google.com/spreadsheets/d/1xgDM68xiM34Lb7pPa9X0VaOqdhswjHKkl6KIk-vu_2"&"Q/edit?gid=0#gid=0"",""Classes!B2:B""),0)),"""")"),"") | D34: 0 | E34: RP Adjustment (Negative) | G34: 0 | H34: Initiative Adjustment (- for negative) | K34: 0 | M34: 0 | N34: 0 | O34: 0 | P34: 0
B35: =IFERROR(__xludf.DUMMYFUNCTION("IFERROR(INDEX(IMPORTRANGE(""https://docs.google.com/spreadsheets/d/1xgDM68xiM34Lb7pPa9X0VaOqdhswjHKkl6KIk-vu_2Q/edit?gid=0#gid=0"",""Classes!C2:C""),MATCH(A35,IMPORTRANGE(""https://docs.google.com/spreadsheets/d/1xgDM68xiM34Lb7pPa9X0VaOqdhswjHKkl6KIk-vu_2"&"Q/edit?gid=0#gid=0"",""Classes!B2:B""),0)),"""")"),"") | D35: 0 | E35: 0 | H35: 0 | M35: Injuries
A36: Weapon | B36: Light/Heavy Attack | C36: Precise Attack | D36: Light Damage | E36: Heavy Damage | F36: Equipment | G36: Guard (Passive) Bonus | H36: Evasion - for negative | I36: Dodge - for negative | J36: Block (Active) Bonus | K36: Initiative Penalty (Positive Number) | L36: Armor Equipped?
B37: =B9 -> 3 | C37: =B9*2 -> 6 | L37: FALSE
B38: =B9 -> 3 | C38: =B9*2 -> 6 | L38: FALSE | M38: Main Hand | N38: FALSE | O38: Head | P38: FALSE
B39: =B9 -> 3 | C39: =B9*2 -> 6 | L39: FALSE | M39: Muscle | N39: FALSE | O39: Wound | P39: FALSE
B40: =B9 -> 3 | C40: =B9*2 -> 6 | L40: FALSE | M40: Spirit Circuit | N40: FALSE | O40: Eye | P40: FALSE
...

Sheet Abilities
A1: Active Ability Name | B1: Cost | C1: Keywords | D1: Range | E1: Requirement | F1: Description | G1: Benefits
B2: {=IF(A2="", "", IFERROR(INDEX('All Abilities'!H:H, MATCH(A2, 'All Abilities'!B:B, 0)), ""))} | C2: {=IF(A2="", "", IFERROR(INDEX('All Abilities'!D:D, MATCH(A2, 'All Abilities'!B:B, 0)), ""))} | D2: {=IF(A2="", "", IFERROR(INDEX('All Abilities'!E:E, MATCH(A2, 'All Abilities'!B:B, 0)), ""))} | E2: {=IF(A2="", "", IFERROR(INDEX('All Abilities'!G:G, MATCH(A2, 'All Abilities'!B:B, 0)), ""))} | F2: {=IF(A2="", "", IFERROR(INDEX('All Abilities'!F:F, MATCH(A2, 'All Abilities'!B:B, 0)), ""))} | G2: {=IF(A2="", "", IFERROR(INDEX('All Abilities'!L:L, MATCH(A2, 'All Abilities'!B:B, 0)), ""))}
B3: {=IF(A3="", "", IFERROR(INDEX('All Abilities'!H:H, MATCH(A3, 'All Abilities'!B:B, 0)), ""))} | C3: {=IF(A3="", "", IFERROR(INDEX('All Abilities'!D:D, MATCH(A3, 'All Abilities'!B:B, 0)), ""))} | D3: {=IF(A3="", "", IFERROR(INDEX('All Abilities'!E:E, MATCH(A3, 'All Abilities'!B:B, 0)), ""))} | E3: {=IF(A3="", "", IFERROR(INDEX('All Abilities'!G:G, MATCH(A3, 'All Abilities'!B:B, 0)), ""))} | F3: {=IF(A3="", "", IFERROR(INDEX('All Abilities'!F:F, MATCH(A3, 'All Abilities'!B:B, 0)), ""))} | G3: {=IF(A3="", "", IFERROR(INDEX('All Abilities'!L:L, MATCH(A3, 'All Abilities'!B:B, 0)), ""))}
B4: {=IF(A4="", "", IFERROR(INDEX('All Abilities'!H:H, MATCH(A4, 'All Abilities'!B:B, 0)), ""))} | C4: {=IF(A4="", "", IFERROR(INDEX('All Abilities'!D:D, MATCH(A4, 'All Abilities'!B:B, 0)), ""))} | D4: {=IF(A4="", "", IFERROR(INDEX('All Abilities'!E:E, MATCH(A4, 'All Abilities'!B:B, 0)), ""))} | E4: {=IF(A4="", "", IFERROR(INDEX('All Abilities'!G:G, MATCH(A4, 'All Abilities'!B:B, 0)), ""))} | F4: {=IF(A4="", "", IFERROR(INDEX('All Abilities'!F:F, MATCH(A4, 'All Abilities'!B:B, 0)), ""))} | G4: {=IF(A4="", "", IFERROR(INDEX('All Abilities'!L:L, MATCH(A4, 'All Abilities'!B:B, 0)), ""))}
B5: {=IF(A5="", "", IFERROR(INDEX('All Abilities'!H:H, MATCH(A5, 'All Abilities'!B:B, 0)), ""))} | C5: {=IF(A5="", "", IFERROR(INDEX('All Abilities'!D:D, MATCH(A5, 'All Abilities'!B:B, 0)), ""))} | D5: {=IF(A5="", "", IFERROR(INDEX('All Abilities'!E:E, MATCH(A5, 'All Abilities'!B:B, 0)), ""))} | E5: {=IF(A5="", "", IFERROR(INDEX('All Abilities'!G:G, MATCH(A5, 'All Abilities'!B:B, 0)), ""))} | F5: {=IF(A5="", "", IFERROR(INDEX('All Abilities'!F:F, MATCH(A5, 'All Abilities'!B:B, 0)), ""))} | G5: {=IF(A5="", "", IFERROR(INDEX('All Abilities'!L:L, MATCH(A5, 'All Abilities'!B:B, 0)), ""))}
B6: {=IF(A6="", "", IFERROR(INDEX('All Abilities'!H:H, MATCH(A6, 'All Abilities'!B:B, 0)), ""))} | C6: {=IF(A6="", "", IFERROR(INDEX('All Abilities'!D:D, MATCH(A6, 'All Abilities'!B:B, 0)), ""))} | D6: {=IF(A6="", "", IFERROR(INDEX('All Abilities'!E:E, MATCH(A6, 'All Abilities'!B:B, 0)), ""))} | E6: {=IF(A6="", "", IFERROR(INDEX('All Abilities'!G:G, MATCH(A6, 'All Abilities'!B:B, 0)), ""))} | F6: {=IF(A6="", "", IFERROR(INDEX('All Abilities'!F:F, MATCH(A6, 'All Abilities'!B:B, 0)), ""))} | G6: {=IF(A6="", "", IFERROR(INDEX('All Abilities'!L:L, MATCH(A6, 'All Abilities'!B:B, 0)), ""))}
B7: {=IF(A7="", "", IFERROR(INDEX('All Abilities'!H:H, MATCH(A7, 'All Abilities'!B:B, 0)), ""))} | C7: {=IF(A7="", "", IFERROR(INDEX('All Abilities'!D:D, MATCH(A7, 'All Abilities'!B:B, 0)), ""))} | D7: {=IF(A7="", "", IFERROR(INDEX('All Abilities'!E:E, MATCH(A7, 'All Abilities'!B:B, 0)), ""))} | E7: {=IF(A7="", "", IFERROR(INDEX('All Abilities'!G:G, MATCH(A7, 'All Abilities'!B:B, 0)), ""))} | F7: {=IF(A7="", "", IFERROR(INDEX('All Abilities'!F:F, MATCH(A7, 'All Abilities'!B:B, 0)), ""))} | G7: {=IF(A7="", "", IFERROR(INDEX('All Abilities'!L:L, MATCH(A7, 'All Abilities'!B:B, 0)), ""))}
B8: {=IF(A8="", "", IFERROR(INDEX('All Abilities'!H:H, MATCH(A8, 'All Abilities'!B:B, 0)), ""))} | C8: {=IF(A8="", "", IFERROR(INDEX('All Abilities'!D:D, MATCH(A8, 'All Abilities'!B:B, 0)), ""))} | D8: {=IF(A8="", "", IFERROR(INDEX('All Abilities'!E:E, MATCH(A8, 'All Abilities'!B:B, 0)), ""))} | E8: {=IF(A8="", "", IFERROR(INDEX('All Abilities'!G:G, MATCH(A8, 'All Abilities'!B:B, 0)), ""))} | F8: {=IF(A8="", "", IFERROR(INDEX('All Abilities'!F:F, MATCH(A8, 'All Abilities'!B:B, 0)), ""))} | G8: {=IF(A8="", "", IFERROR(INDEX('All Abilities'!L:L, MATCH(A8, 'All Abilities'!B:B, 0)), ""))}
B9: {=IF(A9="", "", IFERROR(INDEX('All Abilities'!H:H, MATCH(A9, 'All Abilities'!B:B, 0)), ""))} | C9: {=IF(A9="", "", IFERROR(INDEX('All Abilities'!D:D, MATCH(A9, 'All Abilities'!B:B, 0)), ""))} | D9: {=IF(A9="", "", IFERROR(INDEX('All Abilities'!E:E, MATCH(A9, 'All Abilities'!B:B, 0)), ""))} | E9: {=IF(A9="", "", IFERROR(INDEX('All Abilities'!G:G, MATCH(A9, 'All Abilities'!B:B, 0)), ""))} | F9: {=IF(A9="", "", IFERROR(INDEX('All Abilities'!F:F, MATCH(A9, 'All Abilities'!B:B, 0)), ""))} | G9: {=IF(A9="", "", IFERROR(INDEX('All Abilities'!L:L, MATCH(A9, 'All Abilities'!B:B, 0)), ""))}
B10: {=IF(A10="", "", IFERROR(INDEX('All Abilities'!H:H, MATCH(A10, 'All Abilities'!B:B, 0)), ""))} | C10: {=IF(A10="", "", IFERROR(INDEX('All Abilities'!D:D, MATCH(A10, 'All Abilities'!B:B, 0)), ""))} | D10: {=IF(A10="", "", IFERROR(INDEX('All Abilities'!E:E, MATCH(A10, 'All Abilities'!B:B, 0)), ""))} | E10: {=IF(A10="", "", IFERROR(INDEX('All Abilities'!G:G, MATCH(A10, 'All Abilities'!B:B, 0)), ""))} | F10: {=IF(A10="", "", IFERROR(INDEX('All Abilities'!F:F, MATCH(A10, 'All Abilities'!B:B, 0)), ""))} | G10: {=IF(A10="", "", IFERROR(INDEX('All Abilities'!L:L, MATCH(A10, 'All Abilities'!B:B, 0)), ""))}
B11: {=IF(A11="", "", IFERROR(INDEX('All Abilities'!H:H, MATCH(A11, 'All Abilities'!B:B, 0)), ""))} | C11: {=IF(A11="", "", IFERROR(INDEX('All Abilities'!D:D, MATCH(A11, 'All Abilities'!B:B, 0)), ""))} | D11: {=IF(A11="", "", IFERROR(INDEX('All Abilities'!E:E, MATCH(A11, 'All Abilities'!B:B, 0)), ""))} | E11: {=IF(A11="", "", IFERROR(INDEX('All Abilities'!G:G, MATCH(A11, 'All Abilities'!B:B, 0)), ""))} | F11: {=IF(A11="", "", IFERROR(INDEX('All Abilities'!F:F, MATCH(A11, 'All Abilities'!B:B, 0)), ""))} | G11: {=IF(A11="", "", IFERROR(INDEX('All Abilities'!L:L, MATCH(A11, 'All Abilities'!B:B, 0)), ""))}
B12: {=IF(A12="", "", IFERROR(INDEX('All Abilities'!H:H, MATCH(A12, 'All Abilities'!B:B, 0)), ""))} | C12: {=IF(A12="", "", IFERROR(INDEX('All Abilities'!D:D, MATCH(A12, 'All Abilities'!B:B, 0)), ""))} | D12: {=IF(A12="", "", IFERROR(INDEX('All Abilities'!E:E, MATCH(A12, 'All Abilities'!B:B, 0)), ""))} | E12: {=IF(A12="", "", IFERROR(INDEX('All Abilities'!G:G, MATCH(A12, 'All Abilities'!B:B, 0)), ""))} | F12: {=IF(A12="", "", IFERROR(INDEX('All Abilities'!F:F, MATCH(A12, 'All Abilities'!B:B, 0)), ""))} | G12: {=IF(A12="", "", IFERROR(INDEX('All Abilities'!L:L, MATCH(A12, 'All Abilities'!B:B, 0)), ""))}
B13: {=IF(A13="", "", IFERROR(INDEX('All Abilities'!H:H, MATCH(A13, 'All Abilities'!B:B, 0)), ""))} | C13: {=IF(A13="", "", IFERROR(INDEX('All Abilities'!D:D, MATCH(A13, 'All Abilities'!B:B, 0)), ""))} | D13: {=IF(A13="", "", IFERROR(INDEX('All Abilities'!E:E, MATCH(A13, 'All Abilities'!B:B, 0)), ""))} | E13: {=IF(A13="", "", IFERROR(INDEX('All Abilities'!G:G, MATCH(A13, 'All Abilities'!B:B, 0)), ""))} | F13: {=IF(A13="", "", IFERROR(INDEX('All Abilities'!F:F, MATCH(A13, 'All Abilities'!B:B, 0)), ""))} | G13: {=IF(A13="", "", IFERROR(INDEX('All Abilities'!L:L, MATCH(A13, 'All Abilities'!B:B, 0)), ""))}
... B58: {=IF(A58="", "", IFERROR(INDEX('All Abilities'!H:H, MATCH(A58, 'All Abilities'!B:B, 0)), ""))} | C58: {=IF(A58="", "", IFERROR(INDEX('All Abilities'!D:D, MATCH(A58, 'All Abilities'!B:B, 0)), ""))} | D58: {=IF(A58="", "", IFERROR(INDEX('All Abilities'!E:E, MATCH(A58, 'All Abilities'!B:B, 0)), ""))} | E58: {=IF(A58="", "", IFERROR(INDEX('All Abilities'!G:G, MATCH(A58, 'All Abilities'!B:B, 0)), ""))} | F58: {=IF(A58="", "", IFERROR(INDEX('All Abilities'!F:F, MATCH(A58, 'All Abilities'!B:B, 0)), ""))} | G58: {=IF(A58="", "", IFERROR(INDEX('All Abilities'!L:L, MATCH(A58, 'All Abilities'!B:B, 0)), ""))}
A59: Passive Ability Name | B59: Cost | C59: Keywords | D59: Range | E59: Requirement | F59: Description | G59: Benefits
B60: {=IF(A60="", "", IFERROR(INDEX('All Abilities'!H:H, MATCH(A60, 'All Abilities'!B:B, 0)), ""))} | C60: {=IF(A60="", "", IFERROR(INDEX('All Abilities'!D:D, MATCH(A60, 'All Abilities'!B:B, 0)), ""))} | D60: {=IF(A60="", "", IFERROR(INDEX('All Abilities'!E:E, MATCH(A60, 'All Abilities'!B:B, 0)), ""))} | E60: {=IF(A60="", "", IFERROR(INDEX('All Abilities'!G:G, MATCH(A60, 'All Abilities'!B:B, 0)), ""))} | F60: {=IF(A60="", "", IFERROR(INDEX('All Abilities'!F:F, MATCH(A60, 'All Abilities'!B:B, 0)), ""))} | G60: {=IF(A60="", "", IFERROR(INDEX('All Abilities'!L:L, MATCH(A60, 'All Abilities'!B:B, 0)), ""))}
B61: {=IF(A61="", "", IFERROR(INDEX('All Abilities'!H:H, MATCH(A61, 'All Abilities'!B:B, 0)), ""))} | C61: {=IF(A61="", "", IFERROR(INDEX('All Abilities'!D:D, MATCH(A61, 'All Abilities'!B:B, 0)), ""))} | D61: {=IF(A61="", "", IFERROR(INDEX('All Abilities'!E:E, MATCH(A61, 'All Abilities'!B:B, 0)), ""))} | E61: {=IF(A61="", "", IFERROR(INDEX('All Abilities'!G:G, MATCH(A61, 'All Abilities'!B:B, 0)), ""))} | F61: {=IF(A61="", "", IFERROR(INDEX('All Abilities'!F:F, MATCH(A61, 'All Abilities'!B:B, 0)), ""))} | G61: {=IF(A61="", "", IFERROR(INDEX('All Abilities'!L:L, MATCH(A61, 'All Abilities'!B:B, 0)), ""))}
B62: {=IF(A62="", "", IFERROR(INDEX('All Abilities'!H:H, MATCH(A62, 'All Abilities'!B:B, 0)), ""))} | C62: {=IF(A62="", "", IFERROR(INDEX('All Abilities'!D:D, MATCH(A62, 'All Abilities'!B:B, 0)), ""))} | D62: {=IF(A62="", "", IFERROR(INDEX('All Abilities'!E:E, MATCH(A62, 'All Abilities'!B:B, 0)), ""))} | E62: {=IF(A62="", "", IFERROR(INDEX('All Abilities'!G:G, MATCH(A62, 'All Abilities'!B:B, 0)), ""))} | F62: {=IF(A62="", "", IFERROR(INDEX('All Abilities'!F:F, MATCH(A62, 'All Abilities'!B:B, 0)), ""))} | G62: {=IF(A62="", "", IFERROR(INDEX('All Abilities'!L:L, MATCH(A62, 'All Abilities'!B:B, 0)), ""))}
B63: {=IF(A63="", "", IFERROR(INDEX('All Abilities'!H:H, MATCH(A63, 'All Abilities'!B:B, 0)), ""))} | C63: {=IF(A63="", "", IFERROR(INDEX('All Abilities'!D:D, MATCH(A63, 'All Abilities'!B:B, 0)), ""))} | D63: {=IF(A63="", "", IFERROR(INDEX('All Abilities'!E:E, MATCH(A63, 'All Abilities'!B:B, 0)), ""))} | E63: {=IF(A63="", "", IFERROR(INDEX('All Abilities'!G:G, MATCH(A63, 'All Abilities'!B:B, 0)), ""))} | F63: {=IF(A63="", "", IFERROR(INDEX('All Abilities'!F:F, MATCH(A63, 'All Abilities'!B:B, 0)), ""))} | G63: {=IF(A63="", "", IFERROR(INDEX('All Abilities'!L:L, MATCH(A63, 'All Abilities'!B:B, 0)), ""))}
B64: {=IF(A64="", "", IFERROR(INDEX('All Abilities'!H:H, MATCH(A64, 'All Abilities'!B:B, 0)), ""))} | C64: {=IF(A64="", "", IFERROR(INDEX('All Abilities'!D:D, MATCH(A64, 'All Abilities'!B:B, 0)), ""))} | D64: {=IF(A64="", "", IFERROR(INDEX('All Abilities'!E:E, MATCH(A64, 'All Abilities'!B:B, 0)), ""))} | E64: {=IF(A64="", "", IFERROR(INDEX('All Abilities'!G:G, MATCH(A64, 'All Abilities'!B:B, 0)), ""))} | F64: {=IF(A64="", "", IFERROR(INDEX('All Abilities'!F:F, MATCH(A64, 'All Abilities'!B:B, 0)), ""))} | G64: {=IF(A64="", "", IFERROR(INDEX('All Abilities'!L:L, MATCH(A64, 'All Abilities'!B:B, 0)), ""))}
B65: {=IF(A65="", "", IFERROR(INDEX('All Abilities'!H:H, MATCH(A65, 'All Abilities'!B:B, 0)), ""))} | C65: {=IF(A65="", "", IFERROR(INDEX('All Abilities'!D:D, MATCH(A65, 'All Abilities'!B:B, 0)), ""))} | D65: {=IF(A65="", "", IFERROR(INDEX('All Abilities'!E:E, MATCH(A65, 'All Abilities'!B:B, 0)), ""))} | E65: {=IF(A65="", "", IFERROR(INDEX('All Abilities'!G:G, MATCH(A65, 'All Abilities'!B:B, 0)), ""))} | F65: {=IF(A65="", "", IFERROR(INDEX('All Abilities'!F:F, MATCH(A65, 'All Abilities'!B:B, 0)), ""))} | G65: {=IF(A65="", "", IFERROR(INDEX('All Abilities'!L:L, MATCH(A65, 'All Abilities'!B:B, 0)), ""))}
B66: {=IF(A66="", "", IFERROR(INDEX('All Abilities'!H:H, MATCH(A66, 'All Abilities'!B:B, 0)), ""))} | C66: {=IF(A66="", "", IFERROR(INDEX('All Abilities'!D:D, MATCH(A66, 'All Abilities'!B:B, 0)), ""))} | D66: {=IF(A66="", "", IFERROR(INDEX('All Abilities'!E:E, MATCH(A66, 'All Abilities'!B:B, 0)), ""))} | E66: {=IF(A66="", "", IFERROR(INDEX('All Abilities'!G:G, MATCH(A66, 'All Abilities'!B:B, 0)), ""))} | F66: {=IF(A66="", "", IFERROR(INDEX('All Abilities'!F:F, MATCH(A66, 'All Abilities'!B:B, 0)), ""))} | G66: {=IF(A66="", "", IFERROR(INDEX('All Abilities'!L:L, MATCH(A66, 'All Abilities'!B:B, 0)), ""))}
B67: {=IF(A67="", "", IFERROR(INDEX('All Abilities'!H:H, MATCH(A67, 'All Abilities'!B:B, 0)), ""))} | C67: {=IF(A67="", "", IFERROR(INDEX('All Abilities'!D:D, MATCH(A67, 'All Abilities'!B:B, 0)), ""))} | D67: {=IF(A67="", "", IFERROR(INDEX('All Abilities'!E:E, MATCH(A67, 'All Abilities'!B:B, 0)), ""))} | E67: {=IF(A67="", "", IFERROR(INDEX('All Abilities'!G:G, MATCH(A67, 'All Abilities'!B:B, 0)), ""))} | F67: {=IF(A67="", "", IFERROR(INDEX('All Abilities'!F:F, MATCH(A67, 'All Abilities'!B:B, 0)), ""))} | G67: {=IF(A67="", "", IFERROR(INDEX('All Abilities'!L:L, MATCH(A67, 'All Abilities'!B:B, 0)), ""))}
B68: {=IF(A68="", "", IFERROR(INDEX('All Abilities'!H:H, MATCH(A68, 'All Abilities'!B:B, 0)), ""))} | C68: {=IF(A68="", "", IFERROR(INDEX('All Abilities'!D:D, MATCH(A68, 'All Abilities'!B:B, 0)), ""))} | D68: {=IF(A68="", "", IFERROR(INDEX('All Abilities'!E:E, MATCH(A68, 'All Abilities'!B:B, 0)), ""))} | E68: {=IF(A68="", "", IFERROR(INDEX('All Abilities'!G:G, MATCH(A68, 'All Abilities'!B:B, 0)), ""))} | F68: {=IF(A68="", "", IFERROR(INDEX('All Abilities'!F:F, MATCH(A68, 'All Abilities'!B:B, 0)), ""))} | G68: {=IF(A68="", "", IFERROR(INDEX('All Abilities'!L:L, MATCH(A68, 'All Abilities'!B:B, 0)), ""))}
B69: {=IF(A69="", "", IFERROR(INDEX('All Abilities'!H:H, MATCH(A69, 'All Abilities'!B:B, 0)), ""))} | C69: {=IF(A69="", "", IFERROR(INDEX('All Abilities'!D:D, MATCH(A69, 'All Abilities'!B:B, 0)), ""))} | D69: {=IF(A69="", "", IFERROR(INDEX('All Abilities'!E:E, MATCH(A69, 'All Abilities'!B:B, 0)), ""))} | E69: {=IF(A69="", "", IFERROR(INDEX('All Abilities'!G:G, MATCH(A69, 'All Abilities'!B:B, 0)), ""))} | F69: {=IF(A69="", "", IFERROR(INDEX('All Abilities'!F:F, MATCH(A69, 'All Abilities'!B:B, 0)), ""))} | G69: {=IF(A69="", "", IFERROR(INDEX('All Abilities'!L:L, MATCH(A69, 'All Abilities'!B:B, 0)), ""))}
B70: {=IF(A70="", "", IFERROR(INDEX('All Abilities'!H:H, MATCH(A70, 'All Abilities'!B:B, 0)), ""))} | C70: {=IF(A70="", "", IFERROR(INDEX('All Abilities'!D:D, MATCH(A70, 'All Abilities'!B:B, 0)), ""))} | D70: {=IF(A70="", "", IFERROR(INDEX('All Abilities'!E:E, MATCH(A70, 'All Abilities'!B:B, 0)), ""))} | E70: {=IF(A70="", "", IFERROR(INDEX('All Abilities'!G:G, MATCH(A70, 'All Abilities'!B:B, 0)), ""))} | F70: {=IF(A70="", "", IFERROR(INDEX('All Abilities'!F:F, MATCH(A70, 'All Abilities'!B:B, 0)), ""))} | G70: {=IF(A70="", "", IFERROR(INDEX('All Abilities'!L:L, MATCH(A70, 'All Abilities'!B:B, 0)), ""))}
B71: {=IF(A71="", "", IFERROR(INDEX('All Abilities'!H:H, MATCH(A71, 'All Abilities'!B:B, 0)), ""))} | C71: {=IF(A71="", "", IFERROR(INDEX('All Abilities'!D:D, MATCH(A71, 'All Abilities'!B:B, 0)), ""))} | D71: {=IF(A71="", "", IFERROR(INDEX('All Abilities'!E:E, MATCH(A71, 'All Abilities'!B:B, 0)), ""))} | E71: {=IF(A71="", "", IFERROR(INDEX('All Abilities'!G:G, MATCH(A71, 'All Abilities'!B:B, 0)), ""))} | F71: {=IF(A71="", "", IFERROR(INDEX('All Abilities'!F:F, MATCH(A71, 'All Abilities'!B:B, 0)), ""))} | G71: {=IF(A71="", "", IFERROR(INDEX('All Abilities'!L:L, MATCH(A71, 'All Abilities'!B:B, 0)), ""))}
... B80: {=IF(A80="", "", IFERROR(INDEX('All Abilities'!H:H, MATCH(A80, 'All Abilities'!B:B, 0)), ""))} | C80: {=IF(A80="", "", IFERROR(INDEX('All Abilities'!D:D, MATCH(A80, 'All Abilities'!B:B, 0)), ""))} | D80: {=IF(A80="", "", IFERROR(INDEX('All Abilities'!E:E, MATCH(A80, 'All Abilities'!B:B, 0)), ""))} | E80: {=IF(A80="", "", IFERROR(INDEX('All Abilities'!G:G, MATCH(A80, 'All Abilities'!B:B, 0)), ""))} | F80: {=IF(A80="", "", IFERROR(INDEX('All Abilities'!F:F, MATCH(A80, 'All Abilities'!B:B, 0)), ""))} | G80: {=IF(A80="", "", IFERROR(INDEX('All Abilities'!L:L, MATCH(A80, 'All Abilities'!B:B, 0)), ""))}
A81: 2 | B81: Place Ability to the Left, the roll20 macro will be to the right. | C81: {=SUBSTITUTE(SUBSTITUTE(SUBSTITUTE(SUBSTITUTE(SUBSTITUTE(SUBSTITUTE("&{template:default} {{name=@{name} ❖ {skillname}}} {{Keywords:={keywords}}} {{Range:={range}}} {{Cost:={cost}}} {{Req:={req}}} {{Desc:={desc}}}", "{skillname}", INDIRECT("A"&$A$81)), "{keywords}", INDIRECT("C"&$A$81)), "{range}", INDIRECT("D"&$A$81)), "{cost}", INDIRECT("B"&$A$81)), "{req}", INDIRECT("E"&$A$81)), "{desc}", INDIRECT("F"&$A$81))} -> &{template:default} {{name=@{name} ❖ }} {{Keywords:=}} {{Range:=}} {{Cost:=}} {{Req:=}} {{Desc:=}}

Sheet Breakthrough
A1: Breakthrough | B1: XP Spent | C1: Requirement | D1: Description | E1: Each character starts with 300 exp that can only be used on breakthroughs. This EXP is not added to your spirit core and any exp not spent during this time is removed after the character creation process. Any breakthroughs taken during character creation using this 300xp should be left at 0 XP Spent in the dropdown. | F1: If Taking 'Mixed House' Breakthrough Select Both Chosen Houses
B2: 0 | C2: {=IF(A2="", "", IFERROR(INDEX(Breakthroughs!C:C, MATCH(A2, Breakthroughs!A:A, 0)), ""))} | D2: {=IF(A2="", "", IFERROR(INDEX(Breakthroughs!D:D, MATCH(A2, Breakthroughs!A:A, 0)), ""))}
B3: 0 | C3: {=IF(A3="", "", IFERROR(INDEX(Breakthroughs!C:C, MATCH(A3, Breakthroughs!A:A, 0)), ""))} | D3: {=IF(A3="", "", IFERROR(INDEX(Breakthroughs!D:D, MATCH(A3, Breakthroughs!A:A, 0)), ""))}
B4: 0 | C4: {=IF(A4="", "", IFERROR(INDEX(Breakthroughs!C:C, MATCH(A4, Breakthroughs!A:A, 0)), ""))} | D4: {=IF(A4="", "", IFERROR(INDEX(Breakthroughs!D:D, MATCH(A4, Breakthroughs!A:A, 0)), ""))}
B5: 0 | C5: {=IF(A5="", "", IFERROR(INDEX(Breakthroughs!C:C, MATCH(A5, Breakthroughs!A:A, 0)), ""))} | D5: {=IF(A5="", "", IFERROR(INDEX(Breakthroughs!D:D, MATCH(A5, Breakthroughs!A:A, 0)), ""))}
B6: 0 | C6: {=IF(A6="", "", IFERROR(INDEX(Breakthroughs!C:C, MATCH(A6, Breakthroughs!A:A, 0)), ""))} | D6: {=IF(A6="", "", IFERROR(INDEX(Breakthroughs!D:D, MATCH(A6, Breakthroughs!A:A, 0)), ""))}
B7: 0 | C7: {=IF(A7="", "", IFERROR(INDEX(Breakthroughs!C:C, MATCH(A7, Breakthroughs!A:A, 0)), ""))} | D7: {=IF(A7="", "", IFERROR(INDEX(Breakthroughs!D:D, MATCH(A7, Breakthroughs!A:A, 0)), ""))}
B8: 0 | C8: {=IF(A8="", "", IFERROR(INDEX(Breakthroughs!C:C, MATCH(A8, Breakthroughs!A:A, 0)), ""))} | D8: {=IF(A8="", "", IFERROR(INDEX(Breakthroughs!D:D, MATCH(A8, Breakthroughs!A:A, 0)), ""))}
B9: 0 | C9: {=IF(A9="", "", IFERROR(INDEX(Breakthroughs!C:C, MATCH(A9, Breakthroughs!A:A, 0)), ""))} | D9: {=IF(A9="", "", IFERROR(INDEX(Breakthroughs!D:D, MATCH(A9, Breakthroughs!A:A, 0)), ""))}
B10: 0 | C10: {=IF(A10="", "", IFERROR(INDEX(Breakthroughs!C:C, MATCH(A10, Breakthroughs!A:A, 0)), ""))} | D10: {=IF(A10="", "", IFERROR(INDEX(Breakthroughs!D:D, MATCH(A10, Breakthroughs!A:A, 0)), ""))}
B11: 0 | C11: {=IF(A11="", "", IFERROR(INDEX(Breakthroughs!C:C, MATCH(A11, Breakthroughs!A:A, 0)), ""))} | D11: {=IF(A11="", "", IFERROR(INDEX(Breakthroughs!D:D, MATCH(A11, Breakthroughs!A:A, 0)), ""))}
B12: 0 | C12: {=IF(A12="", "", IFERROR(INDEX(Breakthroughs!C:C, MATCH(A12, Breakthroughs!A:A, 0)), ""))} | D12: {=IF(A12="", "", IFERROR(INDEX(Breakthroughs!D:D, MATCH(A12, Breakthroughs!A:A, 0)), ""))}
B13: 0 | C13: {=IF(A13="", "", IFERROR(INDEX(Breakthroughs!C:C, MATCH(A13, Breakthroughs!A:A, 0)), ""))} | D13: {=IF(A13="", "", IFERROR(INDEX(Breakthroughs!D:D, MATCH(A13, Breakthroughs!A:A, 0)), ""))}
... B16: 0 | C16: {=IF(A16="", "", IFERROR(INDEX(Breakthroughs!C:C, MATCH(A16, Breakthroughs!A:A, 0)), ""))} | D16: {=IF(A16="", "", IFERROR(INDEX(Breakthroughs!D:D, MATCH(A16, Breakthroughs!A:A, 0)), ""))}
B17: 0 | C17: {=IF(A17="", "", IFERROR(INDEX(Breakthroughs!C:C, MATCH(A17, Breakthroughs!A:A, 0)), ""))} | D17: {=IF(A17="", "", IFERROR(INDEX(Breakthroughs!D:D, MATCH(A17, Breakthroughs!A:A, 0)), ""))} | F17: Wi, Homeless
B18: 0 | C18: {=IF(A18="", "", IFERROR(INDEX(Breakthroughs!C:C, MATCH(A18, Breakthroughs!A:A, 0)), ""))} | D18: {=IF(A18="", "", IFERROR(INDEX(Breakthroughs!D:D, MATCH(A18, Breakthroughs!A:A, 0)), ""))}
B19: 0 | C19: {=IF(A19="", "", IFERROR(INDEX(Breakthroughs!C:C, MATCH(A19, Breakthroughs!A:A, 0)), ""))} | D19: {=IF(A19="", "", IFERROR(INDEX(Breakthroughs!D:D, MATCH(A19, Breakthroughs!A:A, 0)), ""))}
B20: 0 | C20: {=IF(A20="", "", IFERROR(INDEX(Breakthroughs!C:C, MATCH(A20, Breakthroughs!A:A, 0)), ""))} | D20: {=IF(A20="", "", IFERROR(INDEX(Breakthroughs!D:D, MATCH(A20, Breakthroughs!A:A, 0)), ""))}
B21: 0 | C21: {=IF(A21="", "", IFERROR(INDEX(Breakthroughs!C:C, MATCH(A21, Breakthroughs!A:A, 0)), ""))} | D21: {=IF(A21="", "", IFERROR(INDEX(Breakthroughs!D:D, MATCH(A21, Breakthroughs!A:A, 0)), ""))}
B22: 0 | C22: {=IF(A22="", "", IFERROR(INDEX(Breakthroughs!C:C, MATCH(A22, Breakthroughs!A:A, 0)), ""))} | D22: {=IF(A22="", "", IFERROR(INDEX(Breakthroughs!D:D, MATCH(A22, Breakthroughs!A:A, 0)), ""))}
B23: 0 | C23: {=IF(A23="", "", IFERROR(INDEX(Breakthroughs!C:C, MATCH(A23, Breakthroughs!A:A, 0)), ""))} | D23: {=IF(A23="", "", IFERROR(INDEX(Breakthroughs!D:D, MATCH(A23, Breakthroughs!A:A, 0)), ""))}
B24: 0 | C24: {=IF(A24="", "", IFERROR(INDEX(Breakthroughs!C:C, MATCH(A24, Breakthroughs!A:A, 0)), ""))} | D24: {=IF(A24="", "", IFERROR(INDEX(Breakthroughs!D:D, MATCH(A24, Breakthroughs!A:A, 0)), ""))}
B25: 0 | C25: {=IF(A25="", "", IFERROR(INDEX(Breakthroughs!C:C, MATCH(A25, Breakthroughs!A:A, 0)), ""))} | D25: {=IF(A25="", "", IFERROR(INDEX(Breakthroughs!D:D, MATCH(A25, Breakthroughs!A:A, 0)), ""))}
B26: 0 | C26: {=IF(A26="", "", IFERROR(INDEX(Breakthroughs!C:C, MATCH(A26, Breakthroughs!A:A, 0)), ""))} | D26: {=IF(A26="", "", IFERROR(INDEX(Breakthroughs!D:D, MATCH(A26, Breakthroughs!A:A, 0)), ""))}
B27: 0 | C27: {=IF(A27="", "", IFERROR(INDEX(Breakthroughs!C:C, MATCH(A27, Breakthroughs!A:A, 0)), ""))} | D27: {=IF(A27="", "", IFERROR(INDEX(Breakthroughs!D:D, MATCH(A27, Breakthroughs!A:A, 0)), ""))}
B28: 0 | C28: {=IF(A28="", "", IFERROR(INDEX(Breakthroughs!C:C, MATCH(A28, Breakthroughs!A:A, 0)), ""))} | D28: {=IF(A28="", "", IFERROR(INDEX(Breakthroughs!D:D, MATCH(A28, Breakthroughs!A:A, 0)), ""))}
B29: 0 | C29: {=IF(A29="", "", IFERROR(INDEX(Breakthroughs!C:C, MATCH(A29, Breakthroughs!A:A, 0)), ""))} | D29: {=IF(A29="", "", IFERROR(INDEX(Breakthroughs!D:D, MATCH(A29, Breakthroughs!A:A, 0)), ""))}
... B37: 0 | C37: {=IF(A37="", "", IFERROR(INDEX(Breakthroughs!C:C, MATCH(A37, Breakthroughs!A:A, 0)), ""))} | D37: {=IF(A37="", "", IFERROR(INDEX(Breakthroughs!D:D, MATCH(A37, Breakthroughs!A:A, 0)), ""))}

Sheet Inventory
A1: Expedition Inventory | B1: Amount | C1: Burden | D1: Clim Cost (Price of 1 Item) | E1: Item Total Clim Value | F1: Description | G1: Burden Total
E2: =SUMPRODUCT((IF(B2="",1,B2)) * (IF(D2="",0,D2))) -> 0 | G2: =SUM(C2:C137) -> 0
E3: =SUMPRODUCT((IF(B3="",1,B3)) * (IF(D3="",0,D3))) -> 0 | G3: Inventory Clim Value | H3: =SUMPRODUCT((IF(B2:B137="",1,B2:B137)) * (IF(D2:D137="",0,D2:D137))) -> 0
E4: =SUMPRODUCT((IF(B4="",1,B4)) * (IF(D4="",0,D4))) -> 0 | G4: Total Character Clim Value | H4: =SUM(H3,Core!L2,'Mirane Locker'!G2) -> 4000
E5: =SUMPRODUCT((IF(B5="",1,B5)) * (IF(D5="",0,D5))) -> 0 | G5: Combat Loadout | H5: Burden
E6: =SUMPRODUCT((IF(B6="",1,B6)) * (IF(D6="",0,D6))) -> 0
E7: =SUMPRODUCT((IF(B7="",1,B7)) * (IF(D7="",0,D7))) -> 0
E8: =SUMPRODUCT((IF(B8="",1,B8)) * (IF(D8="",0,D8))) -> 0
E9: =SUMPRODUCT((IF(B9="",1,B9)) * (IF(D9="",0,D9))) -> 0
E10: =SUMPRODUCT((IF(B10="",1,B10)) * (IF(D10="",0,D10))) -> 0
E11: =SUMPRODUCT((IF(B11="",1,B11)) * (IF(D11="",0,D11))) -> 0
E12: =SUMPRODUCT((IF(B12="",1,B12)) * (IF(D12="",0,D12))) -> 0
E13: =SUMPRODUCT((IF(B13="",1,B13)) * (IF(D13="",0,D13))) -> 0
E14: =SUMPRODUCT((IF(B14="",1,B14)) * (IF(D14="",0,D14))) -> 0
E15: =SUMPRODUCT((IF(B15="",1,B15)) * (IF(D15="",0,D15))) -> 0
E16: =SUMPRODUCT((IF(B16="",1,B16)) * (IF(D16="",0,D16))) -> 0
E17: =SUMPRODUCT((IF(B17="",1,B17)) * (IF(D17="",0,D17))) -> 0
... E31: =SUMPRODUCT((IF(B31="",1,B31)) * (IF(D31="",0,D31))) -> 0
E32: =SUMPRODUCT((IF(B32="",1,B32)) * (IF(D32="",0,D32))) -> 0 | G32: Combat Burden Total | H32: =sum(H6:H31) -> 0
E33: =SUMPRODUCT((IF(B33="",1,B33)) * (IF(D33="",0,D33))) -> 0 | G33: Adventurer's Kit | H33: Burden
E34: =SUMPRODUCT((IF(B34="",1,B34)) * (IF(D34="",0,D34))) -> 0
E35: =SUMPRODUCT((IF(B35="",1,B35)) * (IF(D35="",0,D35))) -> 0
E36: =SUMPRODUCT((IF(B36="",1,B36)) * (IF(D36="",0,D36))) -> 0
E37: =SUMPRODUCT((IF(B37="",1,B37)) * (IF(D37="",0,D37))) -> 0
E38: =SUMPRODUCT((IF(B38="",1,B38)) * (IF(D38="",0,D38))) -> 0
E39: =SUMPRODUCT((IF(B39="",1,B39)) * (IF(D39="",0,D39))) -> 0 | G39: Adventurer's Kit Total Burden Carried | H39: =sum(H33:H38) -> 0
E40: =SUMPRODUCT((IF(B40="",1,B40)) * (IF(D40="",0,D40))) -> 0 | G40: ADVENTURER'S KIT CAN STORE 5 BURDEN MAX IN COMBAT READY STATE
E41: =SUMPRODUCT((IF(B41="",1,B41)) * (IF(D41="",0,D41))) -> 0
E42: =SUMPRODUCT((IF(B42="",1,B42)) * (IF(D42="",0,D42))) -> 0
E43: =SUMPRODUCT((IF(B43="",1,B43)) * (IF(D43="",0,D43))) -> 0
E44: =SUMPRODUCT((IF(B44="",1,B44)) * (IF(D44="",0,D44))) -> 0 | G44: Alchemy Rig | H44: Burden
E45: =SUMPRODUCT((IF(B45="",1,B45)) * (IF(D45="",0,D45))) -> 0
E46: =SUMPRODUCT((IF(B46="",1,B46)) * (IF(D46="",0,D46))) -> 0
E47: =SUMPRODUCT((IF(B47="",1,B47)) * (IF(D47="",0,D47))) -> 0
E48: =SUMPRODUCT((IF(B48="",1,B48)) * (IF(D48="",0,D48))) -> 0
E49: =SUMPRODUCT((IF(B49="",1,B49)) * (IF(D49="",0,D49))) -> 0
E50: =SUMPRODUCT((IF(B50="",1,B50)) * (IF(D50="",0,D50))) -> 0 | G50: Alchemy Rig Burden Total | H50: =SUM(H45:H49) -> 0
E51: =SUMPRODUCT((IF(B51="",1,B51)) * (IF(D51="",0,D51))) -> 0
E52: =SUMPRODUCT((IF(B52="",1,B52)) * (IF(D52="",0,D52))) -> 0
E53: =SUMPRODUCT((IF(B53="",1,B53)) * (IF(D53="",0,D53))) -> 0
...

Sheet Mirane Locker
A1: Mirane Locker | B1: Amount | C1: Item Type | D1: Clim Cost (Price of 1 Item) | E1: Total Item Clim Value | F1: Notes | G1: Mirane Locker Clim Value Total
E2: =SUMPRODUCT((IF(B2="",1,B2)) * (IF(D2="",0,D2))) -> 0 | G2: =SUMPRODUCT((IF(B2:B137="",1,B2:B137)) * (IF(D2:D137="",0,D2:D137))) -> 0
E3: =SUMPRODUCT((IF(B3="",1,B3)) * (IF(D3="",0,D3))) -> 0
E4: =SUMPRODUCT((IF(B4="",1,B4)) * (IF(D4="",0,D4))) -> 0
E5: =SUMPRODUCT((IF(B5="",1,B5)) * (IF(D5="",0,D5))) -> 0
E6: =SUMPRODUCT((IF(B6="",1,B6)) * (IF(D6="",0,D6))) -> 0
E7: =SUMPRODUCT((IF(B7="",1,B7)) * (IF(D7="",0,D7))) -> 0
E8: =SUMPRODUCT((IF(B8="",1,B8)) * (IF(D8="",0,D8))) -> 0
E9: =SUMPRODUCT((IF(B9="",1,B9)) * (IF(D9="",0,D9))) -> 0
E10: =SUMPRODUCT((IF(B10="",1,B10)) * (IF(D10="",0,D10))) -> 0
E11: =SUMPRODUCT((IF(B11="",1,B11)) * (IF(D11="",0,D11))) -> 0
E12: =SUMPRODUCT((IF(B12="",1,B12)) * (IF(D12="",0,D12))) -> 0
E13: =SUMPRODUCT((IF(B13="",1,B13)) * (IF(D13="",0,D13))) -> 0
E14: =SUMPRODUCT((IF(B14="",1,B14)) * (IF(D14="",0,D14))) -> 0
... E137: =SUMPRODUCT((IF(B137="",1,B137)) * (IF(D137="",0,D137))) -> 0

Sheet EXP & Transactions
A1: Event | B1: Date | C1: Amount of Experience Gained | D1: Experience Total | E1: Service or Item Sold/Purchased | F1: Clim Value (Negative for Purchases) | G1: Clim Purchase and Earned Total
A2: Character Creation | B2: N/A | C2: =SUM(1000 + Core!B49 + Core!B50) -> 1000 | D2: =SUM(C2:C166) -> 1000 | E2: Character Creation | F2: =IF(Core!A58, 4000, 3000) + IF(COUNTIF(Breakthrough!A:A,"Rich Parents")>0, 3000, 0) -> 4000 | G2: =SUM(F2:F166) -> 4000
A3: Retirement/Death | B3: N/A | C3: 0 | D3: Slow Starter and Human EXP changes are already accounted for by the checkboxes in the 'Core' tab. Do not add/subtract them here.
E4: Character Creation Purchases | F4: 0

Sheet Leveling Planner
A1: Level Ups | B1: Class | C1: Class Tier | D1: Class Level | E1: Ability Name | F1: Cost | G1: Keywords | H1: Range | I1: Requirement | J1: Description
A2: 1
A3: 2
A4: 3
A5: 4
A6: 5
A7: 6
A8: 7
A9: 8
A10: 9
A11: 10
A12: 11
A13: 12
... A41: 40

Sheet Images

Sheet Backstory

Sheet Journals

Sheet Custom Abilities
A1: Custom Active Ability Name | B1: Cost | C1: Keywords | D1: Range | E1: Requirement | F1: Description | G1: Benefits
A38: Custom Passive Ability Name | B38: Cost | C38: Keywords | D38: Range | E38: Requirement | F38: Description | G38: Benefits

Sheet Basic Gatherer & Crafter Action
A1: Ability Name | B1: Cost | C1: Keywords | D1: Range | E1: Requirement | F1: Description
A2: Basic Craft | B2: 1 Crafting Dice | C2: Rapid | D2: Self | E2: Must be in a crafting session | F2: You add a crafting check to the item.
A3: Beginner's Luck | B3: 1 Crafting Dice | D3: Self | E3: Must be in a crafting session | F3: You do not add your crafting skill to the check, but you roll two d10s and pick the highest one.
A4: Standard Finish | B4: 2 Crafting Dice | D4: Self | E4: Must be in a crafting session | F4: Double the current crafting points and end crafting. Cannot be used if the item being crafted has been modified beyond it's base form (for example, by adding a +1 power bonus to it via blacksmithing).
A5: Steady Craft | B5: 1 Crafting Dice | D5: Self | E5: Must be in a crafting session | F5: You add a crafting check to the item. The crafting dice automatically is a 5.
A6: Basic Strike | B6: 1 Strike Dice | C6: Rapid | D6: Self | E6: Must be in a gathering session | F6: You add a gathering check to the node points to the target node.
A7: Lucky Strike | B7: 1 Strike Dice, 10 Node Points | C7: Rapid | D7: Self | E7: Must be in a gathering session | F7: You add a gathering check to the lucky points to the target node. This strike has a +10 bonus.
A8: Novice's Perseverance | B8: 1 Strike Dice | D8: Self | E8: Must be in a gathering session | F8: You do not add your crafting skill to the check, but you roll two d10s and pick the highest. Can be used against either NP or LP
A9: Back to Basics | B9: 2 Strike Dice | D9: Self | E9: Must be in a gathering session | F9: Convert all LP up to a maximum of 60 to NP.
A10: Iron Focus | B10: 1 Strike Dice, 5 Lucky Points | D10: Self | E10: Must be in a gathering session | F10: Make a gathering check. Afterwards, you gain a +5 bonus to all gathering checks for the rest of this gathering session.
A11: 2 | B11: Place Ability Row Number to the Left, the roll20 macro will be to the right. | C11: {=SUBSTITUTE(SUBSTITUTE(SUBSTITUTE(SUBSTITUTE(SUBSTITUTE(SUBSTITUTE("&{template:default} {{name=@{name} ❖ {skillname}}} {{Keywords:={keywords}}} {{Range:={range}}} {{Cost:={cost}}} {{Req:={req}}} {{Desc:={desc}}}", "{skillname}", INDIRECT("A"&$A$11)), "{cost}", INDIRECT("B"&$A$11)), "{keywords}", INDIRECT("C"&$A$11)), "{range}", INDIRECT("D"&$A$11)), "{req}", INDIRECT("E"&$A$11)), "{desc}", INDIRECT("F"&$A$11))} -> &{template:default} {{name=@{name} ❖ Basic Craft}} {{Keywords:=Rapid}} {{Range:=Self}} {{Cost:=1 Crafting Dice}} {{Req:=Must be in a crafting session}} {{Desc:=You add a crafting check to the item.}}

Sheet All Abilities
B1: =IFERROR(__xludf.DUMMYFUNCTION("IMPORTRANGE(""https://docs.google.com/spreadsheets/d/1xgDM68xiM34Lb7pPa9X0VaOqdhswjHKkl6KIk-vu_2Q/edit?gid=404700120#gid=404700120"", ""Abilities!B1:B1500"")"),"Name") -> Name | D1: =IFERROR(__xludf.DUMMYFUNCTION("IMPORTRANGE(""https://docs.google.com/spreadsheets/d/1xgDM68xiM34Lb7pPa9X0VaOqdhswjHKkl6KIk-vu_2Q/edit?gid=404700120#gid=404700120"", ""Abilities!F1:F1500"")"),"Keywords") -> Keywords | E1: =IFERROR(__xludf.DUMMYFUNCTION("IMPORTRANGE(""https://docs.google.com/spreadsheets/d/1xgDM68xiM34Lb7pPa9X0VaOqdhswjHKkl6KIk-vu_2Q/edit?gid=404700120#gid=404700120"", ""Abilities!G1:G1500"")"),"Range") -> Range | F1: =IFERROR(__xludf.DUMMYFUNCTION("IMPORTRANGE(""https://docs.google.com/spreadsheets/d/1xgDM68xiM34Lb7pPa9X0VaOqdhswjHKkl6KIk-vu_2Q/edit?gid=404700120#gid=404700120"", ""Abilities!I1:I1500"")"),"Description") -> Description | G1: =IFERROR(__xludf.DUMMYFUNCTION("IMPORTRANGE(""https://docs.google.com/spreadsheets/d/1xgDM68xiM34Lb7pPa9X0VaOqdhswjHKkl6KIk-vu_2Q/edit?gid=404700120#gid=404700120"", ""Abilities!H1:H1500"")"),"Requirement") -> Requirement | H1: =IFERROR(__xludf.DUMMYFUNCTION("IMPORTRANGE(""https://docs.google.com/spreadsheets/d/1xgDM68xiM34Lb7pPa9X0VaOqdhswjHKkl6KIk-vu_2Q/edit?gid=404700120#gid=404700120"", ""Abilities!L1:L1500"")"),"Total cost") -> Total cost | I1: =IFERROR(__xludf.DUMMYFUNCTION("IMPORTRANGE(""https://docs.google.com/spreadsheets/d/1xgDM68xiM34Lb7pPa9X0VaOqdhswjHKkl6KIk-vu_2Q/edit?gid=404700120#gid=404700120"", ""Abilities!C1:C1500"")"),"AP cost") -> AP cost | J1: =IFERROR(__xludf.DUMMYFUNCTION("IMPORTRANGE(""https://docs.google.com/spreadsheets/d/1xgDM68xiM34Lb7pPa9X0VaOqdhswjHKkl6KIk-vu_2Q/edit?gid=404700120#gid=404700120"", ""Abilities!D1:D1500"")"),"Mana cost") -> Mana cost | K1: =IFERROR(__xludf.DUMMYFUNCTION("IMPORTRANGE(""https://docs.google.com/spreadsheets/d/1xgDM68xiM34Lb7pPa9X0VaOqdhswjHKkl6KIk-vu_2Q/edit?gid=404700120#gid=404700120"", ""Abilities!E1:E1500"")"),"RP cost") -> RP cost | L1: =IFERROR(__xludf.DUMMYFUNCTION("IMPORTRANGE(""https://docs.google.com/spreadsheets/d/1xgDM68xiM34Lb7pPa9X0VaOqdhswjHKkl6KIk-vu_2Q/edit?gid=404700120#gid=404700120"", ""Abilities!J1:J1500"")"),"Benefits") -> Benefits
B2: =IFERROR(__xludf.DUMMYFUNCTION("""COMPUTED_VALUE"""),"Abjurer's Blast") -> Abjurer's Blast | D2: =IFERROR(__xludf.DUMMYFUNCTION("""COMPUTED_VALUE"""),"Rapid, Spell") -> Rapid, Spell | E2: =IFERROR(__xludf.DUMMYFUNCTION("""COMPUTED_VALUE"""),"10ft") -> 10ft | F2: =IFERROR(__xludf.DUMMYFUNCTION("""COMPUTED_VALUE"""),"You make a Light (1 AP), Heavy (2 AP) or Precise (2 AP) attack against the target that deals Arcane damage. This spell does not provoke attacks of opportunity.") -> You make a Light (1 AP), Heavy (2 AP) or Precise (2 AP) attack against the target that deals Arcane damage. This spell does not provoke attacks of opportunity. | G2: =IFERROR(__xludf.DUMMYFUNCTION("""COMPUTED_VALUE"""),"") | H2: =IFERROR(__xludf.DUMMYFUNCTION("""COMPUTED_VALUE"""),"1 AP") -> 1 AP | I2: =IFERROR(__xludf.DUMMYFUNCTION("""COMPUTED_VALUE"""),"1 AP") -> 1 AP | J2: =IFERROR(__xludf.DUMMYFUNCTION("""COMPUTED_VALUE"""),"") | K2: =IFERROR(__xludf.DUMMYFUNCTION("""COMPUTED_VALUE"""),"") | L2: =IFERROR(__xludf.DUMMYFUNCTION("""COMPUTED_VALUE"""),"")
B3: =IFERROR(__xludf.DUMMYFUNCTION("""COMPUTED_VALUE"""),"Absorb Ice") -> Absorb Ice | D3: =IFERROR(__xludf.DUMMYFUNCTION("""COMPUTED_VALUE"""),"Rapid") -> Rapid | E3: =IFERROR(__xludf.DUMMYFUNCTION("""COMPUTED_VALUE"""),"Self") -> Self | F3: =IFERROR(__xludf.DUMMYFUNCTION("""COMPUTED_VALUE"""),"You gain Absorb Ice, which gives you Damage Reduction 100 Frost against the triggering damage. After the damage resolves, if the caster is not you, someone allied to you or from an effect made by you or an ally, you gain Temporary HP until the end of the "&"encounter equal to the amount of damage this ability reduces. Any on hit effects from the damage do not apply if you took 0 damage from it because of your DR.") -> You gain Absorb Ice, which gives you Damage Reduction 100 Frost against the triggering damage. After the damage resolves, if the caster is not you, someone allied to you or from an effect made by you or an ally, you gain Temporary HP until the end of the encounter equal to the amount of damage this ability reduces. Any on hit effects from the damage do not apply if you took 0 damage from it because of your DR. | G3: =IFERROR(__xludf.DUMMYFUNCTION("""COMPUTED_VALUE"""),"You're about to take Frost Damage.") -> You're about to take Frost Damage. | H3: =IFERROR(__xludf.DUMMYFUNCTION("""COMPUTED_VALUE"""),"1 RP") -> 1 RP | I3: =IFERROR(__xludf.DUMMYFUNCTION("""COMPUTED_VALUE"""),"") | J3: =IFERROR(__xludf.DUMMYFUNCTION("""COMPUTED_VALUE"""),"") | K3: =IFERROR(__xludf.DUMMYFUNCTION("""COMPUTED_VALUE"""),"1 RP") -> 1 RP | L3: =IFERROR(__xludf.DUMMYFUNCTION("""COMPUTED_VALUE"""),"")
B4: =IFERROR(__xludf.DUMMYFUNCTION("""COMPUTED_VALUE"""),"Accelerando") -> Accelerando | D4: =IFERROR(__xludf.DUMMYFUNCTION("""COMPUTED_VALUE"""),"Encounter Start") -> Encounter Start | E4: =IFERROR(__xludf.DUMMYFUNCTION("""COMPUTED_VALUE"""),"120ft") -> 120ft | F4: =IFERROR(__xludf.DUMMYFUNCTION("""COMPUTED_VALUE"""),"Grant yourself or an ally +4 initiative.") -> Grant yourself or an ally +4 initiative. | G4: =IFERROR(__xludf.DUMMYFUNCTION("""COMPUTED_VALUE"""),"") | H4: =IFERROR(__xludf.DUMMYFUNCTION("""COMPUTED_VALUE"""),"") | I4: =IFERROR(__xludf.DUMMYFUNCTION("""COMPUTED_VALUE"""),"") | J4: =IFERROR(__xludf.DUMMYFUNCTION("""COMPUTED_VALUE"""),"") | K4: =IFERROR(__xludf.DUMMYFUNCTION("""COMPUTED_VALUE"""),"") | L4: =IFERROR(__xludf.DUMMYFUNCTION("""COMPUTED_VALUE"""),"")
B5: =IFERROR(__xludf.DUMMYFUNCTION("""COMPUTED_VALUE"""),"Accelerating Strike") -> Accelerating Strike | D5: =IFERROR(__xludf.DUMMYFUNCTION("""COMPUTED_VALUE"""),"") | E5: =IFERROR(__xludf.DUMMYFUNCTION("""COMPUTED_VALUE"""),"Melee Weapon Range") -> Melee Weapon Range | F5: =IFERROR(__xludf.DUMMYFUNCTION("""COMPUTED_VALUE"""),"You make a Heavy Attack against the target. Afterwards, you gain Accelerating Strike, which increases your Initiative by up to 2.") -> You make a Heavy Attack against the target. Afterwards, you gain Accelerating Strike, which increases your Initiative by up to 2. | G5: =IFERROR(__xludf.DUMMYFUNCTION("""COMPUTED_VALUE"""),"") | H5: =IFERROR(__xludf.DUMMYFUNCTION("""COMPUTED_VALUE"""),"2 AP, 1 MP") -> 2 AP, 1 MP | I5: =IFERROR(__xludf.DUMMYFUNCTION("""COMPUTED_VALUE"""),"2 AP") -> 2 AP | J5: =IFERROR(__xludf.DUMMYFUNCTION("""COMPUTED_VALUE"""),"1 MP") -> 1 MP | K5: =IFERROR(__xludf.DUMMYFUNCTION("""COMPUTED_VALUE"""),"") | L5: =IFERROR(__xludf.DUMMYFUNCTION("""COMPUTED_VALUE"""),"")
B6: =IFERROR(__xludf.DUMMYFUNCTION("""COMPUTED_VALUE"""),"Adaptive Defense") -> Adaptive Defense | D6: =IFERROR(__xludf.DUMMYFUNCTION("""COMPUTED_VALUE"""),"Rapid") -> Rapid | E6: =IFERROR(__xludf.DUMMYFUNCTION("""COMPUTED_VALUE"""),"Self") -> Self | F6: =IFERROR(__xludf.DUMMYFUNCTION("""COMPUTED_VALUE"""),"You take the Block Action. You then gain 4 Adaptive Defense (Type) which grants you Damage Reduction 4 against that damage type until the end of your next turn. You can only have one instance of Adaptive Defense at a time.") -> You take the Block Action. You then gain 4 Adaptive Defense (Type) which grants you Damage Reduction 4 against that damage type until the end of your next turn. You can only have one instance of Adaptive Defense at a time. | G6: =IFERROR(__xludf.DUMMYFUNCTION("""COMPUTED_VALUE"""),"") | H6: =IFERROR(__xludf.DUMMYFUNCTION("""COMPUTED_VALUE"""),"2 MP, 1 RP") -> 2 MP, 1 RP | I6: =IFERROR(__xludf.DUMMYFUNCTION("""COMPUTED_VALUE"""),"") | J6: =IFERROR(__xludf.DUMMYFUNCTION("""COMPUTED_VALUE"""),"2 MP") -> 2 MP | K6: =IFERROR(__xludf.DUMMYFUNCTION("""COMPUTED_VALUE"""),"1 RP") -> 1 RP | L6: =IFERROR(__xludf.DUMMYFUNCTION("""COMPUTED_VALUE"""),"")
B7: =IFERROR(__xludf.DUMMYFUNCTION("""COMPUTED_VALUE"""),"Advanced Artificing") -> Advanced Artificing | D7: =IFERROR(__xludf.DUMMYFUNCTION("""COMPUTED_VALUE"""),"") | E7: =IFERROR(__xludf.DUMMYFUNCTION("""COMPUTED_VALUE"""),"") | F7: =IFERROR(__xludf.DUMMYFUNCTION("""COMPUTED_VALUE"""),"Artifice Modification B Cost: X crafting points Description: You add a B-Type modification to an artifice. See the Universal Artifice mods page as well as the individual weapon page for details. Each modification has its own cost. Weapon Modification B Co"&"st: X Crafting Points Description: You add an B-Type modification to the weapon. See the Universal Weapon page as well as the individual weapon page for details. Each modification has its own cost.") -> Artifice Modification B Cost: X crafting points Description: You add a B-Type modification to an artifice. See the Universal Artifice mods page as well as the individual weapon page for details. Each modification has its own cost. Weapon Modification B Cost: X Crafting Points Description: You add an B-Type modification to the weapon. See the Universal Weapon page as well as the individual weapon page for details. Each modification has its own cost. | G7: =IFERROR(__xludf.DUMMYFUNCTION("""COMPUTED_VALUE"""),"") | H7: =IFERROR(__xludf.DUMMYFUNCTION("""COMPUTED_VALUE"""),"") | I7: =IFERROR(__xludf.DUMMYFUNCTION("""COMPUTED_VALUE"""),"") | J7: =IFERROR(__xludf.DUMMYFUNCTION("""COMPUTED_VALUE"""),"") | K7: =IFERROR(__xludf.DUMMYFUNCTION("""COMPUTED_VALUE"""),"") | L7: =IFERROR(__xludf.DUMMYFUNCTION("""COMPUTED_VALUE"""),"")
B8: =IFERROR(__xludf.DUMMYFUNCTION("""COMPUTED_VALUE"""),"Aerial Crashdown") -> Aerial Crashdown | D8: =IFERROR(__xludf.DUMMYFUNCTION("""COMPUTED_VALUE"""),"") | E8: =IFERROR(__xludf.DUMMYFUNCTION("""COMPUTED_VALUE"""),"60ft") -> 60ft | F8: =IFERROR(__xludf.DUMMYFUNCTION("""COMPUTED_VALUE"""),"You and your mount crash down on the target. You move towards the target and your mount makes a Heavy attack against it. On damage, the target is knocked prone.") -> You and your mount crash down on the target. You move towards the target and your mount makes a Heavy attack against it. On damage, the target is knocked prone. | G8: =IFERROR(__xludf.DUMMYFUNCTION("""COMPUTED_VALUE"""),"You are mounted on a flying mount and the target is at least 20ft below you.") -> You are mounted on a flying mount and the target is at least 20ft below you. | H8: =IFERROR(__xludf.DUMMYFUNCTION("""COMPUTED_VALUE"""),"2 AP") -> 2 AP | I8: =IFERROR(__xludf.DUMMYFUNCTION("""COMPUTED_VALUE"""),"2 AP") -> 2 AP | J8: =IFERROR(__xludf.DUMMYFUNCTION("""COMPUTED_VALUE"""),"") | K8: =IFERROR(__xludf.DUMMYFUNCTION("""COMPUTED_VALUE"""),"") | L8: =IFERROR(__xludf.DUMMYFUNCTION("""COMPUTED_VALUE"""),"")
B9: =IFERROR(__xludf.DUMMYFUNCTION("""COMPUTED_VALUE"""),"Aerial Loop") -> Aerial Loop | D9: =IFERROR(__xludf.DUMMYFUNCTION("""COMPUTED_VALUE"""),"") | E9: =IFERROR(__xludf.DUMMYFUNCTION("""COMPUTED_VALUE"""),"Self or Mount") -> Self or Mount | F9: =IFERROR(__xludf.DUMMYFUNCTION("""COMPUTED_VALUE"""),"You and your mount take the Dodge action and gain a +5 bonus to evasion against the attack.") -> You and your mount take the Dodge action and gain a +5 bonus to evasion against the attack. | G9: =IFERROR(__xludf.DUMMYFUNCTION("""COMPUTED_VALUE"""),"You are mounted on a flying mount and you or your mount are the target of a ranged attack") -> You are mounted on a flying mount and you or your mount are the target of a ranged attack | H9: =IFERROR(__xludf.DUMMYFUNCTION("""COMPUTED_VALUE"""),"1 MP, 1 RP") -> 1 MP, 1 RP | I9: =IFERROR(__xludf.DUMMYFUNCTION("""COMPUTED_VALUE"""),"") | J9: =IFERROR(__xludf.DUMMYFUNCTION("""COMPUTED_VALUE"""),"1 MP") -> 1 MP | K9: =IFERROR(__xludf.DUMMYFUNCTION("""COMPUTED_VALUE"""),"1 RP") -> 1 RP | L9: =IFERROR(__xludf.DUMMYFUNCTION("""COMPUTED_VALUE"""),"")
B10: =IFERROR(__xludf.DUMMYFUNCTION("""COMPUTED_VALUE"""),"Aerial Mode Switch") -> Aerial Mode Switch | D10: =IFERROR(__xludf.DUMMYFUNCTION("""COMPUTED_VALUE"""),"Quick, Rapid, Aerial Mage") -> Quick, Rapid, Aerial Mage | E10: =IFERROR(__xludf.DUMMYFUNCTION("""COMPUTED_VALUE"""),"Self") -> Self | F10: =IFERROR(__xludf.DUMMYFUNCTION("""COMPUTED_VALUE"""),"You switch between hover and aerial mode. Hover mode allows you to attack with normal attacks with one hand. Your airships movement speed is reduced to 10ft while in hover mode. While in Aerial Mode you cannot use any attacks or actions that are not airsh"&"ip weapons or have the Aerial Mage keyword.") -> You switch between hover and aerial mode. Hover mode allows you to attack with normal attacks with one hand. Your airships movement speed is reduced to 10ft while in hover mode. While in Aerial Mode you cannot use any attacks or actions that are not airship weapons or have the Aerial Mage keyword. | G10: =IFERROR(__xludf.DUMMYFUNCTION("""COMPUTED_VALUE"""),"Riding Aerial Staff.") -> Riding Aerial Staff. | H10: =IFERROR(__xludf.DUMMYFUNCTION("""COMPUTED_VALUE"""),"0 AP") -> 0 AP | I10: =IFERROR(__xludf.DUMMYFUNCTION("""COMPUTED_VALUE"""),"0 AP") -> 0 AP | J10: =IFERROR(__xludf.DUMMYFUNCTION("""COMPUTED_VALUE"""),"") | K10: =IFERROR(__xludf.DUMMYFUNCTION("""COMPUTED_VALUE"""),"") | L10: =IFERROR(__xludf.DUMMYFUNCTION("""COMPUTED_VALUE"""),"")
B11: =IFERROR(__xludf.DUMMYFUNCTION("""COMPUTED_VALUE"""),"Aftershock") -> Aftershock | D11: =IFERROR(__xludf.DUMMYFUNCTION("""COMPUTED_VALUE"""),"Rage, Half Pierce") -> Rage, Half Pierce | E11: =IFERROR(__xludf.DUMMYFUNCTION("""COMPUTED_VALUE"""),"Melee Weapon Range") -> Melee Weapon Range | F11: =IFERROR(__xludf.DUMMYFUNCTION("""COMPUTED_VALUE"""),"You attack with such force that you create aftershocks when you miss your attack, dealing Half Pierce Physical Damage equal to your Power to the target and all enemies within 5ft of it. If the target Dodged the triggering attack, this damage is reduced to"&" half your Power instead. If your attack targets multiple enemies, this only applies if you miss all enemies.") -> You attack with such force that you create aftershocks when you miss your attack, dealing Half Pierce Physical Damage equal to your Power to the target and all enemies within 5ft of it. If the target Dodged the triggering attack, this damage is reduced to half your Power instead. If your attack targets multiple enemies, this only applies if you miss all enemies. | G11: =IFERROR(__xludf.DUMMYFUNCTION("""COMPUTED_VALUE"""),"You missed a Heavy melee attack with a Two-Handed Melee Weapon.") -> You missed a Heavy melee attack with a Two-Handed Melee Weapon. | H11: =IFERROR(__xludf.DUMMYFUNCTION("""COMPUTED_VALUE"""),"1 MP, 0 RP") -> 1 MP, 0 RP | I11: =IFERROR(__xludf.DUMMYFUNCTION("""COMPUTED_VALUE"""),"") | J11: =IFERROR(__xludf.DUMMYFUNCTION("""COMPUTED_VALUE"""),"1 MP") -> 1 MP | K11: =IFERROR(__xludf.DUMMYFUNCTION("""COMPUTED_VALUE"""),"0 RP") -> 0 RP | L11: =IFERROR(__xludf.DUMMYFUNCTION("""COMPUTED_VALUE"""),"")
B12: =IFERROR(__xludf.DUMMYFUNCTION("""COMPUTED_VALUE"""),"Aimed Shot") -> Aimed Shot | D12: =IFERROR(__xludf.DUMMYFUNCTION("""COMPUTED_VALUE"""),"Lock On") -> Lock On | E12: =IFERROR(__xludf.DUMMYFUNCTION("""COMPUTED_VALUE"""),"Ranged Weapon Range") -> Ranged Weapon Range | F12: =IFERROR(__xludf.DUMMYFUNCTION("""COMPUTED_VALUE"""),"You make a Heavy Attack against the target.") -> You make a Heavy Attack against the target. | G12: =IFERROR(__xludf.DUMMYFUNCTION("""COMPUTED_VALUE"""),"") | H12: =IFERROR(__xludf.DUMMYFUNCTION("""COMPUTED_VALUE"""),"2 AP, 2 MP") -> 2 AP, 2 MP | I12: =IFERROR(__xludf.DUMMYFUNCTION("""COMPUTED_VALUE"""),"2 AP") -> 2 AP | J12: =IFERROR(__xludf.DUMMYFUNCTION("""COMPUTED_VALUE"""),"2 MP") -> 2 MP | K12: =IFERROR(__xludf.DUMMYFUNCTION("""COMPUTED_VALUE"""),"") | L12: =IFERROR(__xludf.DUMMYFUNCTION("""COMPUTED_VALUE"""),"")
